Workbook

Sheet Cover
B2: WINDMILL APARTMENTS
B3: Value-Add Multifamily Acquisition Underwriting
B5: Property Address: | C5: 10705 E US Highway 136, Indianapolis, IN 46234
B6: Broker: | C6: Marcus & Millichap | Julia Evinger (BOR)
B7: Unit Count: | C7: 33 units (15 Studios / 17 1BR/1BA / 1 2BR/2BA)
B8: Year Built: | C8: 1980
B9: Asking Price: | C9: 3120000
B10: Price / Unit: | C10: =C9/33 -> 94545.455
B12: MODEL STRUCTURE
B13: Assumptions | C13: All key inputs. Edit the yellow cells.
B14: Rent Roll | C14: Unit mix, in-place vs. market rents
B15: T-12 | C15: Actual trailing 12 operating statement from broker
B16: Pro Forma | C16: Year 1 stabilized underwriting
B17: Debt Schedule | C17: 5-year amortization
B18: Cash Flow | C18: 5-year hold cash flows
B19: Returns | C19: IRR, equity multiple, cash-on-cash
B20: Sensitivity | C20: Price × Exit Cap tables
B21: Rent Comps | C21: Comps pulled from Apartments.com
B24: COLOR KEY
B25: Blue text = hardcoded input
B26: Black text = formula
B27: Green text = cross-sheet reference
B28: Yellow fill = user-editable assumption
B30: IMPORTANT — READ FIRST
B31: 1. Broker's OM shows a 'Current' NOI of $248,070 (7.95% cap). The actual T-12 NOI is $212,573 (6.81% cap).
B32: The $35K gap is created by removing all payroll ($43,900), cutting marketing 50%, and reducing G&A.
B33: This model underwrites to the T-12 with honest adjustments — not to the broker's pro forma.
B35: 2. Rent comp verification (Apartments.com, July 2026):
B36: Windmill studios: 226-267 sqft at $725-$812 = $3.17-$3.21/sqft — ALREADY above market on $/sqft basis.
B37: Windmill 1BRs: 464-506 sqft at $999-$1,050 = $2.17-$2.26/sqft — comparable to market $/sqft.
... B40: 3. All formulas trace back to the Assumptions tab. Change inputs there, everything downstream updates.

Sheet Assumptions
B2: UNDERWRITING ASSUMPTIONS
B3: Yellow cells are editable inputs. Change these to test different scenarios.
A5: ACQUISITION
B6: Purchase Price ($) | C6: 3120000
B7: Number of Units | C7: 33
B8: Price per Unit | C8: =C6/C7 -> 94545.455
B9: Closing Costs (% of price) | C9: 0.02
B10: Total Acquisition Cost | C10: =C6+C6*C9 -> 3182400
A12: FINANCING
B13: Loan-to-Value (LTV) | C13: 0.7
B14: Loan Amount | C14: =C6*C13 -> 2184000
B15: Interest Rate | C15: 0.0675
B16: Amortization (years) | C16: 25
B17: Loan Term (years) | C17: 5
B18: Equity Required | C18: =C10-C14 -> 998400
A20: INCOME (Year 1 Stabilized)
B21: Gross Potential Rent — Y1 ($) | C21: 377760
B22: Physical Vacancy | C22: 0.05
B23: Collections Loss | C23: 0.035
B24: Concessions | C24: 0.015
B25: Loss to Lease | C25: 0.02
B26: Other Income — Utility Reimbursements | C26: 74763
B27: Other Income — Fees & Late/Pet/Misc | C27: 27955
B28: Annual Rent Growth (Years 2-5) | C28: 0.025
B29: Annual Other Income Growth | C29: 0.02
A31: OPERATING EXPENSES (Year 1)
B32: Real Estate Taxes ($) | C32: 29200
B33: Insurance ($) | C33: 11550
B34: Utilities — total ($) | C34: 44479
B35: Repairs & Maintenance ($) | C35: 16500
B36: Marketing & Advertising ($) | C36: 8250
B37: Payroll ($) | C37: 0
B38: Landscaping / Contract Services ($) | C38: 5703
B39: General & Administrative ($) | C39: 10064
B40: Legal & Professional ($) | C40: 4771
B41: Internet Service Contract ($) | C41: 8449
B42: Management Fee (% of EGI) | C42: 0.08
B43: Annual Expense Growth (Years 2-5) | C43: 0.03
B44: Replacement Reserves per Unit ($) | C44: 300
A46: EXIT ASSUMPTIONS
...

Sheet Rent Roll
B2: RENT ROLL SUMMARY
B3: From broker's OM, page 23. As of 5/26/2026.
B5: Unit Type | C5: # Units | D5: Avg SqFt | E5: % Mix | F5: Current Rent | G5: Current Rent/SF | H5: Monthly Income | I5: Market Rent | J5: Monthly Potential
B6: Studio A Reno | C6: 9 | D6: 226 | E6: =C6/33 -> 0.27272727 | F6: 725 | G6: =F6/D6 -> 3.2079646 | H6: =C6*F6 -> 6525 | I6: 800 | J6: =C6*I6 -> 7200
B7: Studio B Reno | C7: 4 | D7: 256 | E7: =C7/33 -> 0.12121212 | F7: 812 | G7: =F7/D7 -> 3.171875 | H7: =C7*F7 -> 3248 | I7: 895 | J7: =C7*I7 -> 3580
B8: Studio B Classic | C8: 2 | D8: 267 | E8: =C8/33 -> 0.060606061 | F8: 805 | G8: =F8/D8 -> 3.0149813 | H8: =C8*F8 -> 1610 | I8: 825 | J8: =C8*I8 -> 1650
B9: 1 Bed - 1 Bath Reno | C9: 13 | D9: 464 | E9: =C9/33 -> 0.39393939 | F9: 1007 | G9: =F9/D9 -> 2.1702586 | H9: =C9*F9 -> 13091 | I9: 1050 | J9: =C9*I9 -> 13650
B10: 1 Bed - 1 Bath Classic | C10: 4 | D10: 506 | E10: =C10/33 -> 0.12121212 | F10: 999 | G10: =F10/D10 -> 1.9743083 | H10: =C10*F10 -> 3996 | I10: 1000 | J10: =C10*I10 -> 4000
B11: 2 Bed - 2 Bath Reno | C11: 1 | D11: 952 | E11: =C11/33 -> 0.03030303 | F11: 1375 | G11: =F11/D11 -> 1.4443277 | H11: =C11*F11 -> 1375 | I11: 1400 | J11: =C11*I11 -> 1400
B12: TOTALS / WEIGHTED AVG | C12: =SUM(C6:C11) -> 33 | D12: =SUMPRODUCT(C6:C11,D6:D11)/C12 -> 381.81818 | E12: =SUM(E6:E11) -> 1 | F12: =H12/C12 -> 904.39394 | G12: =F12/D12 -> 2.3686508 | H12: =SUM(H6:H11) -> 29845 | I12: =J12/C12 -> 953.93939 | J12: =SUM(J6:J11) -> 31480
B14: GROSS ANNUALIZED RENT | F14: Current: | G14: =H12*12 -> 358140 | I14: Potential: | J14: =J12*12 -> 377760
B17: OCCUPANCY (per Yardi rent roll 5/26/2026)
B18: Occupied Units: | C18: 31
B19: Vacant Units: | C19: 2
B20: Physical Occupancy: | C20: =C18/33 -> 0.93939394
B21: Note: Broker OM claims 97% occupancy. Actual rent roll = 93.94%.

Sheet T-12
B2: T-12 OPERATING STATEMENT
B3: Actual trailing 12 months: May 2025 - April 2026. Source: Broker's Yardi export.
B5: Line Item | C5: T-12 Total | D5: Per Unit | E5: Notes
B6: INCOME
B7: Gross Market Rent | C7: 355296 | D7: =C7/33 -> 10766.545
B8: Loss / Gain to Lease | C8: -674 | D8: =C8/33 -> -20.424242
B9: Gross Scheduled Rent | C9: =SUM(C7:C8) -> 354622 | D9: =C9/33 -> 10746.121
B10: Physical Vacancy | C10: -17649 | D10: =C10/33 -> -534.81818
B11: Collections Loss (write-offs) | C11: -19894 | D11: =C11/33 -> -602.84848 | E11: Elevated — real collection issues
B12: Concessions | C12: -6587 | D12: =C12/33 -> -199.60606
B13: Net Rental Income | C13: =C9+SUM(C10:C12) -> 310492 | D13: =C13/33 -> 9408.8485
B14: Utility Reimbursements & Fees | C14: 74763 | D14: =C14/33 -> 2265.5455
B15: Other Income (fees, late, pet, etc.) | C15: 27955 | D15: =C15/33 -> 847.12121
B16: TOTAL REVENUE (EGI) | C16: =C13+C14+C15 -> 413210 | D16: =C16/33 -> 12521.515
B18: EXPENSES
B19: Payroll | C19: 43900 | D19: =C19/33 -> 1330.303 | E19: Removed in pro forma (third-party PM)
B20: Repairs & Maintenance | C20: 7947 | D20: =C20/33 -> 240.81818 | E20: Unsustainably low — increased in pro forma
B21: Marketing & Advertising | C21: 11951 | D21: =C21/33 -> 362.15152
B22: Landscaping | C22: 5703 | D22: =C22/33 -> 172.81818
B23: Contract Services | C23: 0 | D23: =C23/33 -> 0 | E23: Rolled into Landscaping to match OM p.24
B24: General & Administrative | C24: 10064 | D24: =C24/33 -> 304.9697 | E24: Includes turnover, admin fees
B25: Legal & Professional | C25: 4771 | D25: =C25/33 -> 144.57576
B26: Internet Service Contract | C26: 8449 | D26: =C26/33 -> 256.0303
B27: Utilities (Electric) | C27: 25941 | D27: =C27/33 -> 786.09091
B28: Utilities (Gas) | C28: 3400 | D28: =C28/33 -> 103.0303
B29: Utilities (Water/Sewer) | C29: 9121 | D29: =C29/33 -> 276.39394
B30: Trash Removal | C30: 6017 | D30: =C30/33 -> 182.33333
B31: Management Fee | C31: 25962 | D31: =C31/33 -> 786.72727
B32: Real Estate Taxes | C32: 27132 | D32: =C32/33 -> 822.18182
B33: Insurance | C33: 10278 | D33: =C33/33 -> 311.45455
B34: TOTAL OPERATING EXPENSES | C34: =SUM(C19:C33) -> 200636 | D34: =C34/33 -> 6079.8788
B36: NET OPERATING INCOME (T-12) | C36: =C16-C34 -> 212574 | D36: =C36/33 -> 6441.6364
B37: Expense Ratio | C37: =C34/C16 -> 0.48555456
B38: Cap Rate on Asking Price | C38: =C36/Assumptions!C6 -> 0.068132692 | E38: ← This is the HONEST cap rate. Broker claims 7.95%.

Sheet Pro Forma
B2: YEAR 1 STABILIZED PRO FORMA
B3: Underwritten with honest assumptions. All inputs live in the Assumptions tab.
B5: Line Item | C5: Year 1 | D5: Per Unit | E5: Basis
B6: INCOME
B7: Gross Potential Rent | C7: =Assumptions!C21 -> 377760 | D7: =C7/33 -> 11447.273 | E7: From Assumptions
B8: Less: Loss to Lease | C8: =-C7*Assumptions!C25 -> -7555.2 | D8: =C8/33 -> -228.94545
B9: Less: Physical Vacancy | C9: =-C7*Assumptions!C22 -> -18888 | D9: =C9/33 -> -572.36364
B10: Less: Collections Loss | C10: =-C7*Assumptions!C23 -> -13221.6 | D10: =C10/33 -> -400.65455
B11: Less: Concessions | C11: =-C7*Assumptions!C24 -> -5666.4 | D11: =C11/33 -> -171.70909
B12: Effective Rental Income | C12: =SUM(C7:C11) -> 332428.8 | D12: =C12/33 -> 10073.6
B13: Plus: Utility Reimbursements | C13: =Assumptions!C26 -> 74763 | D13: =C13/33 -> 2265.5455
B14: Plus: Other Income | C14: =Assumptions!C27 -> 27955 | D14: =C14/33 -> 847.12121
B15: EFFECTIVE GROSS INCOME (EGI) | C15: =C12+C13+C14 -> 435146.8 | D15: =C15/33 -> 13186.267
B17: OPERATING EXPENSES
B18: Real Estate Taxes | C18: =Assumptions!C32 -> 29200 | D18: =C18/33 -> 884.84848
B19: Insurance | C19: =Assumptions!C33 -> 11550 | D19: =C19/33 -> 350
B20: Utilities (all) | C20: =Assumptions!C34 -> 44479 | D20: =C20/33 -> 1347.8485
B21: Repairs & Maintenance | C21: =Assumptions!C35 -> 16500 | D21: =C21/33 -> 500
B22: Marketing & Advertising | C22: =Assumptions!C36 -> 8250 | D22: =C22/33 -> 250
B23: Payroll | C23: =Assumptions!C37 -> 0 | D23: =C23/33 -> 0
B24: Landscaping / Contract | C24: =Assumptions!C38 -> 5703 | D24: =C24/33 -> 172.81818
B25: General & Administrative | C25: =Assumptions!C39 -> 10064 | D25: =C25/33 -> 304.9697
B26: Legal & Professional | C26: =Assumptions!C40 -> 4771 | D26: =C26/33 -> 144.57576
B27: Internet Service Contract | C27: =Assumptions!C41 -> 8449 | D27: =C27/33 -> 256.0303
B28: Management Fee (8% of EGI) | C28: =C15*Assumptions!C42 -> 34811.744 | D28: =C28/33 -> 1054.9013
B29: TOTAL OPERATING EXPENSES | C29: =SUM(C18:C28) -> 173777.74 | D29: =C29/33 -> 5265.9922
B30: Expense Ratio (% of EGI) | C30: =C29/C15 -> 0.3993543
B32: NET OPERATING INCOME | C32: =C15-C29 -> 261369.06 | D32: =C32/33 -> 7920.2744
B33: Less: Replacement Reserves | C33: =-Assumptions!C44*33 -> -9900 | D33: =C33/33 -> -300
B34: NOI AFTER RESERVES | C34: =C32+C33 -> 251469.06 | D34: =C34/33 -> 7620.2744
B36: IMPLIED CAP RATE ANALYSIS
B37: Cap Rate on NOI (before reserves) | C37: =C32/Assumptions!C6 -> 0.083772133
B38: Cap Rate on NOI (after reserves) | C38: =C34/Assumptions!C6 -> 0.080599056 | E38: Compare to broker's claimed 7.95% cap and market cap of 6.38%.

Sheet Debt Schedule
B2: DEBT SCHEDULE
B3: 5-year amortization with 25-year amort period.
B5: Loan Amount: | C5: =Assumptions!C14 -> 2184000
B6: Interest Rate: | C6: =Assumptions!C15 -> 0.0675
B7: Amortization: | C7: =Assumptions!C16 -> 25
B8: Annual Debt Service: | C8: =-PMT(C6,C7,C5) -> 183209.02 | E8: ← annual P&I payment
B11: AMORTIZATION SCHEDULE
B12: Year | C12: Beginning Balance | D12: Interest | E12: Principal | F12: Total Payment | G12: Ending Balance
B13: 1 | C13: =$C$5 -> 2184000 | D13: =C13*$C$6 -> 147420 | E13: =$C$8-D13 -> 35789.015 | F13: =$C$8 -> 183209.02 | G13: =C13-E13 -> 2148211
B14: 2 | C14: =G13 -> 2148211 | D14: =C14*$C$6 -> 145004.24 | E14: =$C$8-D14 -> 38204.774 | F14: =$C$8 -> 183209.02 | G14: =C14-E14 -> 2110006.2
B15: 3 | C15: =G14 -> 2110006.2 | D15: =C15*$C$6 -> 142425.42 | E15: =$C$8-D15 -> 40783.596 | F15: =$C$8 -> 183209.02 | G15: =C15-E15 -> 2069222.6
B16: 4 | C16: =G15 -> 2069222.6 | D16: =C16*$C$6 -> 139672.53 | E16: =$C$8-D16 -> 43536.489 | F16: =$C$8 -> 183209.02 | G16: =C16-E16 -> 2025686.1
B17: 5 | C17: =G16 -> 2025686.1 | D17: =C17*$C$6 -> 136733.81 | E17: =$C$8-D17 -> 46475.202 | F17: =$C$8 -> 183209.02 | G17: =C17-E17 -> 1979210.9

Sheet Cash Flow
B2: 5-YEAR CASH FLOW PROJECTION
B3: All figures grow per Assumptions tab. Debt service from Debt Schedule.
B5: Line Item | C5: Year 1 | D5: Year 2 | E5: Year 3 | F5: Year 4 | G5: Year 5
B7: INCOME
B8: Gross Potential Rent | C8: =Assumptions!C21 -> 377760 | D8: =C8*(1+Assumptions!C28) -> 387204 | E8: =D8*(1+Assumptions!C28) -> 396884.1 | F8: =E8*(1+Assumptions!C28) -> 406806.2 | G8: =F8*(1+Assumptions!C28) -> 416976.36
B9: Less: Loss to Lease | C9: =-C8*Assumptions!C25 -> -7555.2 | D9: =-D8*Assumptions!C25 -> -7744.08 | E9: =-E8*Assumptions!C25 -> -7937.682 | F9: =-F8*Assumptions!C25 -> -8136.1241 | G9: =-G8*Assumptions!C25 -> -8339.5272
B10: Less: Physical Vacancy | C10: =-C8*Assumptions!C22 -> -18888 | D10: =-D8*Assumptions!C22 -> -19360.2 | E10: =-E8*Assumptions!C22 -> -19844.205 | F10: =-F8*Assumptions!C22 -> -20340.31 | G10: =-G8*Assumptions!C22 -> -20848.818
B11: Less: Collections Loss | C11: =-C8*Assumptions!C23 -> -13221.6 | D11: =-D8*Assumptions!C23 -> -13552.14 | E11: =-E8*Assumptions!C23 -> -13890.943 | F11: =-F8*Assumptions!C23 -> -14238.217 | G11: =-G8*Assumptions!C23 -> -14594.173
B12: Less: Concessions | C12: =-C8*Assumptions!C24 -> -5666.4 | D12: =-D8*Assumptions!C24 -> -5808.06 | E12: =-E8*Assumptions!C24 -> -5953.2615 | F12: =-F8*Assumptions!C24 -> -6102.093 | G12: =-G8*Assumptions!C24 -> -6254.6454
B13: Effective Rental Income | C13: =SUM(C8:C12) -> 332428.8 | D13: =SUM(D8:D12) -> 340739.52 | E13: =SUM(E8:E12) -> 349258.01 | F13: =SUM(F8:F12) -> 357989.46 | G13: =SUM(G8:G12) -> 366939.19
B14: Utility Reimbursements | C14: =Assumptions!C26 -> 74763 | D14: =C14*(1+Assumptions!C29) -> 76258.26 | E14: =D14*(1+Assumptions!C29) -> 77783.425 | F14: =E14*(1+Assumptions!C29) -> 79339.094 | G14: =F14*(1+Assumptions!C29) -> 80925.876
B15: Other Income | C15: =Assumptions!C27 -> 27955 | D15: =C15*(1+Assumptions!C29) -> 28514.1 | E15: =D15*(1+Assumptions!C29) -> 29084.382 | F15: =E15*(1+Assumptions!C29) -> 29666.07 | G15: =F15*(1+Assumptions!C29) -> 30259.391
B16: EFFECTIVE GROSS INCOME | C16: =C13+C14+C15 -> 435146.8 | D16: =D13+D14+D15 -> 445511.88 | E16: =E13+E14+E15 -> 456125.82 | F16: =F13+F14+F15 -> 466994.62 | G16: =G13+G14+G15 -> 478124.46
B18: OPERATING EXPENSES
B19: Real Estate Taxes | C19: =Assumptions!C32 -> 29200 | D19: =C19*(1+Assumptions!C43) -> 30076 | E19: =D19*(1+Assumptions!C43) -> 30978.28 | F19: =E19*(1+Assumptions!C43) -> 31907.628 | G19: =F19*(1+Assumptions!C43) -> 32864.857
B20: Insurance | C20: =Assumptions!C33 -> 11550 | D20: =C20*(1+Assumptions!C43) -> 11896.5 | E20: =D20*(1+Assumptions!C43) -> 12253.395 | F20: =E20*(1+Assumptions!C43) -> 12620.997 | G20: =F20*(1+Assumptions!C43) -> 12999.627
B21: Utilities | C21: =Assumptions!C34 -> 44479 | D21: =C21*(1+Assumptions!C43) -> 45813.37 | E21: =D21*(1+Assumptions!C43) -> 47187.771 | F21: =E21*(1+Assumptions!C43) -> 48603.404 | G21: =F21*(1+Assumptions!C43) -> 50061.506
B22: Repairs & Maintenance | C22: =Assumptions!C35 -> 16500 | D22: =C22*(1+Assumptions!C43) -> 16995 | E22: =D22*(1+Assumptions!C43) -> 17504.85 | F22: =E22*(1+Assumptions!C43) -> 18029.996 | G22: =F22*(1+Assumptions!C43) -> 18570.895
B23: Marketing & Advertising | C23: =Assumptions!C36 -> 8250 | D23: =C23*(1+Assumptions!C43) -> 8497.5 | E23: =D23*(1+Assumptions!C43) -> 8752.425 | F23: =E23*(1+Assumptions!C43) -> 9014.9978 | G23: =F23*(1+Assumptions!C43) -> 9285.4477
B24: Payroll | C24: =Assumptions!C37 -> 0 | D24: =C24*(1+Assumptions!C43) -> 0 | E24: =D24*(1+Assumptions!C43) -> 0 | F24: =E24*(1+Assumptions!C43) -> 0 | G24: =F24*(1+Assumptions!C43) -> 0
B25: Landscaping / Contract | C25: =Assumptions!C38 -> 5703 | D25: =C25*(1+Assumptions!C43) -> 5874.09 | E25: =D25*(1+Assumptions!C43) -> 6050.3127 | F25: =E25*(1+Assumptions!C43) -> 6231.8221 | G25: =F25*(1+Assumptions!C43) -> 6418.7767
B26: General & Administrative | C26: =Assumptions!C39 -> 10064 | D26: =C26*(1+Assumptions!C43) -> 10365.92 | E26: =D26*(1+Assumptions!C43) -> 10676.898 | F26: =E26*(1+Assumptions!C43) -> 10997.205 | G26: =F26*(1+Assumptions!C43) -> 11327.121
B27: Legal & Professional | C27: =Assumptions!C40 -> 4771 | D27: =C27*(1+Assumptions!C43) -> 4914.13 | E27: =D27*(1+Assumptions!C43) -> 5061.5539 | F27: =E27*(1+Assumptions!C43) -> 5213.4005 | G27: =F27*(1+Assumptions!C43) -> 5369.8025
B28: Internet Service | C28: =Assumptions!C41 -> 8449 | D28: =C28*(1+Assumptions!C43) -> 8702.47 | E28: =D28*(1+Assumptions!C43) -> 8963.5441 | F28: =E28*(1+Assumptions!C43) -> 9232.4504 | G28: =F28*(1+Assumptions!C43) -> 9509.4239
B29: Management Fee (% of EGI) | C29: =C16*Assumptions!C42 -> 34811.744 | D29: =D16*Assumptions!C42 -> 35640.95 | E29: =E16*Assumptions!C42 -> 36490.065 | F29: =F16*Assumptions!C42 -> 37359.57 | G29: =G16*Assumptions!C42 -> 38249.957
B30: TOTAL OPERATING EXPENSES | C30: =SUM(C19:C29) -> 173777.74 | D30: =SUM(D19:D29) -> 178775.93 | E30: =SUM(E19:E29) -> 183919.09 | F30: =SUM(F19:F29) -> 189211.47 | G30: =SUM(G19:G29) -> 194657.41
B32: NET OPERATING INCOME | C32: =C16-C30 -> 261369.06 | D32: =D16-D30 -> 266735.95 | E32: =E16-E30 -> 272206.72 | F32: =F16-F30 -> 277783.15 | G32: =G16-G30 -> 283467.05
B33: Less: Replacement Reserves | C33: =-Assumptions!C44*33 -> -9900 | D33: =-Assumptions!C44*33 -> -9900 | E33: =-Assumptions!C44*33 -> -9900 | F33: =-Assumptions!C44*33 -> -9900 | G33: =-Assumptions!C44*33 -> -9900
B34: Less: Debt Service | C34: ='Debt Schedule'!F13*-1 -> -183209.02 | D34: ='Debt Schedule'!F14*-1 -> -183209.02 | E34: ='Debt Schedule'!F15*-1 -> -183209.02 | F34: ='Debt Schedule'!F16*-1 -> -183209.02 | G34: ='Debt Schedule'!F17*-1 -> -183209.02
B35: CASH FLOW AFTER DEBT SERVICE | C35: =C32+C33+C34 -> 68260.041 | D35: =D32+D33+D34 -> 73626.934 | E35: =E32+E33+E34 -> 79097.705 | F35: =F32+F33+F34 -> 84674.136 | G35: =G32+G33+G34 -> 90358.032
B37: Debt Service Coverage Ratio (DSCR) | C37: =C32/(-C34) -> 1.4266168 | D37: =D32/(-D34) -> 1.4559106 | E37: =E32/(-E34) -> 1.4857714 | F37: =F32/(-F34) -> 1.516209 | G37: =G32/(-G34) -> 1.5472331
B38: Cash-on-Cash Return | C38: =C35/Assumptions!C18 -> 0.068369432 | D38: =D35/Assumptions!C18 -> 0.073744926 | E38: =E35/Assumptions!C18 -> 0.079224465 | F38: =F35/Assumptions!C18 -> 0.084809832 | G38: =G35/Assumptions!C18 -> 0.090502836

Sheet Returns
B2: RETURNS SUMMARY
B3: IRR, equity multiple, exit assumptions.
B5: EXIT (YEAR 5)
B6: Year 5 NOI | C6: ='Cash Flow'!G32 -> 283467.05
B7: Exit Cap Rate | C7: =Assumptions!C47 -> 0.075
B8: Gross Sale Price | C8: =C6/C7 -> 3779560.6
B9: Cost of Sale | C9: =-C8*Assumptions!C48 -> -188978.03
B10: Loan Balance at Sale | C10: =-'Debt Schedule'!G17 -> -1979210.9 | D10: ← Year 5 ending balance
B11: NET SALE PROCEEDS | C11: =C8+C9+C10 -> 1611371.7
B13: CASH FLOWS FOR IRR
B14: Year 0 — Initial Equity | C14: =-Assumptions!C18 -> -998400
B15: Year 1 — Cash Flow | C15: ='Cash Flow'!C35 -> 68260.041
B16: Year 2 — Cash Flow | C16: ='Cash Flow'!D35 -> 73626.934
B17: Year 3 — Cash Flow | C17: ='Cash Flow'!E35 -> 79097.705
B18: Year 4 — Cash Flow | C18: ='Cash Flow'!F35 -> 84674.136
B19: Year 5 — Cash Flow + Net Sale | C19: ='Cash Flow'!G35+C11 -> 1701729.7
B21: RETURNS
B22: IRR (Levered) | C22: =IRR(C14:C19) -> 0.16589154
B23: Equity Multiple | C23: =SUM(C15:C19)/-C14 -> 2.0106055
B24: Total Equity Invested | C24: =-C14 -> 998400
B25: Total Cash Distributed | C25: =SUM(C15:C19) -> 2007388.5
B26: Net Profit | C26: =SUM(C14:C19) -> 1008988.5

Sheet Sensitivity
B2: SENSITIVITY ANALYSIS
B3: How IRR changes across purchase prices and exit cap rates.
B5: Note: These tables show what IRR would result at various purchase prices and exit caps.
B6: To compute exact values, change the assumptions and observe the Returns tab.
B7: The values below are illustrative — showing which cells to test manually.
B9: IRR by Purchase Price × Exit Cap
B10: Purchase Price → | C10: 2600000 | D10: 2750000 | E10: 2900000 | F10: 3050000 | G10: 3120000 | H10: 3250000
B11: Exit Cap ↓
B12: 0.065 | C12: See Returns | D12: See Returns | E12: See Returns | F12: See Returns | G12: See Returns | H12: See Returns
B13: 0.07 | C13: See Returns | D13: See Returns | E13: See Returns | F13: See Returns | G13: See Returns | H13: See Returns
B14: 0.075 | C14: See Returns | D14: See Returns | E14: See Returns | F14: See Returns | G14: See Returns | H14: See Returns
B15: 0.08 | C15: See Returns | D15: See Returns | E15: See Returns | F15: See Returns | G15: See Returns | H15: See Returns
B16: 0.085 | C16: See Returns | D16: See Returns | E16: See Returns | F16: See Returns | G16: See Returns | H16: See Returns
B17: 0.09 | C17: See Returns | D17: See Returns | E17: See Returns | F17: See Returns | G17: See Returns | H17: See Returns
B20: How to use this table:
B21: 1. Note current settings: Purchase Price and Exit Cap on the Assumptions tab.
B22: 2. Change either input to a value from this grid.
B23: 3. Read the resulting IRR from the Returns tab.
B24: 4. Restore the base case when done.
B27: KEY REFERENCE POINTS
B28: Broker's claimed cap rate: | C28: 0.0795
B29: T-12 actual cap rate at ask: | C29: 0.0681
B30: Brownsburg submarket cap (per OM): | C30: 0.0638
B31: Model's Year 1 cap on ask (honest UW): | C31: ='Pro Forma'!C32/Assumptions!C6 -> 0.083772133

Sheet Rent Comps
B2: RENT COMPS — INDEPENDENT VERIFICATION
B3: Sourced from Apartments.com, July 2026. Distances estimated.
B5: Property | C5: Submarket | D5: Distance (mi) | E5: Unit Type | F5: SqFt | G5: Rent | H5: Rent/SqFt
B6: Eagle Creek by Spark Living | C6: Indianapolis 46234 | D6: 2 | E6: 1BR | F6: 940 | G6: 1177 | H6: =G6/F6 -> 1.2521277
B7: The Landing (2023 build) | C7: Indianapolis 46234 | D7: 2 | E7: 1BR | F7: 956 | G7: 1435 | H7: =G7/F7 -> 1.501046
B8: Steeplechase at Shiloh Crossing | C8: Avon 46123 | D8: 4 | E8: 1BR | F8: 769 | G8: 1215 | H8: =G8/F8 -> 1.579974
B9: Steeplechase at Shiloh Crossing — Renovated | C9: Avon 46123 | D9: 4 | E9: 1BR Renovated | F9: 769 | G9: 1435 | H9: =G9/F9 -> 1.8660598
B10: Regency Preserve (duplex) | C10: Avon 46123 | D10: 4 | E10: 1BR | F10: 863 | G10: 1275 | H10: =G10/F10 -> 1.4774044
B11: The Coil (Broad Ripple) | C11: Indianapolis 46220 | D11: 12 | E11: Studio | F11: 532 | G11: 1495 | H11: =G11/F11 -> 2.8101504
B12: The Coil (Broad Ripple) | C12: Indianapolis 46220 | D12: 12 | E12: Studio | F12: 574 | G12: 1395 | H12: =G12/F12 -> 2.4303136
B13: Rise on Meridian (Downtown) | C13: Indianapolis 46225 | D13: 10 | E13: Studio | F13: 400 | G13: 1284 | H13: =G13/F13 -> 3.21
B14: Rise on Meridian (Downtown) | C14: Indianapolis 46225 | D14: 10 | E14: Studio | F14: 528 | G14: 1341 | H14: =G14/F14 -> 2.5397727
B15: Vivio on Tenth (student) | C15: Indianapolis 46222 | D15: 8 | E15: Studio | F15: 401 | G15: 1199 | H15: =G15/F15 -> 2.9900249
B16: Lake Castleton | C16: Indianapolis 46256 | D16: 15 | E16: Studio | F16: 431 | G16: 1051 | H16: =G16/F16 -> 2.4385151
B18: SUBJECT — WINDMILL APARTMENTS
B19: Windmill — Studio A Reno | C19: Indianapolis 46234 | D19: 0 | E19: Studio | F19: 226 | G19: 725 | H19: =G19/F19 -> 3.2079646
B20: Windmill — Studio B Reno | C20: Indianapolis 46234 | D20: 0 | E20: Studio | F20: 256 | G20: 812 | H20: =G20/F20 -> 3.171875
B21: Windmill — 1BR/1BA Reno | C21: Indianapolis 46234 | D21: 0 | E21: 1BR | F21: 464 | G21: 1050 | H21: =G21/F21 -> 2.262931
B22: Windmill — 1BR/1BA Classic | C22: Indianapolis 46234 | D22: 0 | E22: 1BR | F22: 506 | G22: 999 | H22: =G22/F22 -> 1.9743083
B25: ANALYSIS
B26: 1. Windmill's 1BR rent/sqft ($2.10-$2.26) is comparable to Eagle Creek at $1.25/sqft — Windmill is ABOVE market on $/sqft basis.
B27: 2. Windmill's studios at $3.17-$3.21/sqft are AT OR ABOVE the top of the studio comp range ($2.10-$3.21/sqft) — those comps are urban Broad Ripple/Downtown.
B28: 3. Broker's 'below-market rent' story is largely FALSE. Unit size is the constraint, not rent.
B29: 4. Reasonable rent lift per renovated unit is $25-$50/month, not the $75-$100 broker implies.
B30: 5. Value-add thesis is weakened. Main upside comes from operations (mgmt change, R&M discipline) not rent.
